// exception in java

In Java, an exception is an event that disrupts the normal flow of the program's instructions during execution.
When an exceptional circumstance arises within a method,
the method creates an object and hands it off to the runtime system.

code:

class Test{
    public static void main(String[] args)
    {System.out.println("main methid startded");
    int a = 10 , b=0 , c;
    c = a/b ;
    System.out.println(c);
    System.out.println("main methid ended");}
}

//output

main methid startde
ERROR!
Exception in thread "main" java.lang.ArithmeticException: / by zero
	at Test.main(Test.java:5)

=== Code Exited With Errors ===



// correct the code caused 

why  exception occured in java programm

code:
class Test{
    public static void main(String[] args)
    {System.out.println("main methid startded");
    int a = 10 , b=0 , c;
    try{
    c = a/b ;
    System.out.println(c);}
    catch(ArithmeticException p){
    System.out.println(p);}
    System.out.println("main methid ended");}
}

// output 

java -cp /tmp/n1iUYwGg9v/Test
main methid startded
java.lang.ArithmeticException: / by zero
main methid ended

=== Code Execution Successful ===


// note if exption is there in try block then catch block will executed
// if exption is not there in try block then try block will execute

// code
class Test{
    public static void main(String[] args)
    {System.out.println("main methid startded");
    int a = 10 , b=2 , c;
    try{
    c = a/b ;
    System.out.println(c);}
    catch(ArithmeticException p){
    System.out.println(p);}
    System.out.println("main method ended");}
}

// output

java -cp /tmp/D7P4UzfAC0/Test
main methid startded
5
main methid ended

=== Code Execution Successful ===





/// multiple try and catch 


class Multi{
    public static void main(String[] args)
    {
        try{
            int a= 10,b = 2, c;
            c = a/b;
            System.out.println(c);
            int arr[] = {10,20,30};
             System.out.println(arr[0]);
             String str = null ;
              System.out.println(str.toUpperCase());
        }
        catch(ArrayIndexOutOfBoundsException a)
        { System.out.println("Array exception");
    }
    catch(ArithmeticException b)
    { System.out.println("Arithmetic Exception");}
    catch(NumberFormatException c )
    { System.out.println("number exceptions");}
    catch(Exception d)
    { System.out.println("All Exception");}}
}





/// code 

 finallay block 
 
whater we write will get execut

class Hand {public static void main(String[] args )
{
   try {
       System.out.println("Learn");
       int a=20; int b=2,c;
       c = a/b;
        System.out.println(c);
         System.out.println("Like");
         
   }
   catch(Exception e)
   { System.out.println("can not not divide by b");
}
finally { System.out.println("share");}
 System.out.println("main method ended");}
}




output// 

java -cp /tmp/zvacCitwVz/Hand
Learn
10
Like
share
main method ended

=== Code Execution Successful ===
